Workbook

Sheet SELL_FIREWALL
A1: SELL_ALLOWED_FINAL
A2: YES

Sheet RISK_ENVELOPE_LOCK
A1: KILL_SWITCH
A2: OK

Sheet SYSTEM_HEARTBEAT
A1: GLOBAL_STATUS
A2: RUN

Sheet FORENSIC_LOGIC_MATRIX
A1: Source File | B1: Sheet | C1: Cell | D1: Formula / Logic
A2: DYZEN_CAPITAL_OS_100_PERCENT_PDF_COMPLIANT.xlsx | B2: MASTER_DASHBOARD | C2: A1 | D2: DYZEN CAPITAL OS — FULL INSTITUTIONAL HARDENED VERSION
A3: DYZEN_CAPITAL_OS_100_PERCENT_PDF_COMPLIANT.xlsx | B3: MASTER_DASHBOARD | C3: A4 | D3: Global Exposure Cap %
A4: DYZEN_CAPITAL_OS_100_PERCENT_PDF_COMPLIANT.xlsx | B4: MASTER_DASHBOARD | C4: A6 | D4: Free Capital
A5: DYZEN_CAPITAL_OS_100_PERCENT_PDF_COMPLIANT.xlsx | B5: MASTER_DASHBOARD | C5: A8 | D5: Current Drawdown %
A6: DYZEN_CAPITAL_OS_100_PERCENT_PDF_COMPLIANT.xlsx | B6: CORRELATION_MATRIX | C6: A7 | D6: Cluster Risk Factor
A7: DYZEN_CAPITAL_OS_100_PERCENT_PDF_COMPLIANT.xlsx | B7: DRAWDOWN_ENGINE | C7: A1 | D7: Defensive Threshold
A8: DYZEN_CAPITAL_OS_100_PERCENT_PDF_COMPLIANT.xlsx | B8: DRAWDOWN_ENGINE | C8: A2 | D8: Critical Threshold
A9: DYZEN_CAPITAL_OS_100_PERCENT_PDF_COMPLIANT.xlsx | B9: DRAWDOWN_ENGINE | C9: A4 | D9: Current DD
A10: DYZEN_CAPITAL_OS_100_PERCENT_PDF_COMPLIANT.xlsx | B10: DRAWDOWN_ENGINE | C10: A6 | D10: Risk Mode
A11: DYZEN_CAPITAL_OS_100_PERCENT_PDF_COMPLIANT.xlsx | B11: REGIME_ENGINE | C11: A7 | D11: Regime
A12: DYZEN_CAPITAL_OS_100_PERCENT_PDF_COMPLIANT.xlsx | B12: REGIME_ENGINE | C12: A9 | D12: Regime Multiplier
A13: DYZEN_CAPITAL_OS_100_PERCENT_PDF_COMPLIANT.xlsx | B13: EXECUTION_TICKET | C13: A4 | D13: Regime Adjusted Size
A14: DYZEN_CAPITAL_OS_100_PERCENT_PDF_COMPLIANT.xlsx | B14: EXECUTION_TICKET | C14: B4 | D14: =B3*REGIME_ENGINE!B9
A15: DYZEN_CAPITAL_OS_100_PERCENT_PDF_COMPLIANT.xlsx | B15: EXECUTION_TICKET | C15: A5 | D15: Drawdown Adjusted Size
A16: DYZEN_CAPITAL_OS_100_PERCENT_PDF_COMPLIANT.xlsx | B16: EXECUTION_TICKET | C16: B5 | D16: =B4*DRAWDOWN_ENGINE!B8
A17: DYZEN_CAPITAL_OS_100_PERCENT_PDF_COMPLIANT.xlsx | B17: EXECUTION_TICKET | C17: B7 | D17: =IF(AND(FAILURE_ARCHITECTURE!B6="ACTIVE",DRAWDOWN_ENGINE!B6<>"CRITICAL"),"APPROVED","REJECTED")
A18: DYZEN_CAPITAL_OS_100_PERCENT_PDF_COMPLIANT.xlsx | B18: EXECUTION_TICKET | C18: A9 | D18: Open Risk Check
A19: DYZEN_CAPITAL_OS_100_PERCENT_PDF_COMPLIANT.xlsx | B19: EXECUTION_TICKET | C19: B9 | D19: =OPEN_RISK_ENGINE!B9
A20: DYZEN_CAPITAL_OS_100_PERCENT_PDF_COMPLIANT.xlsx | B20: GOVERNANCE_LOG | C20: C1 | D20: Regime
A21: DYZEN_CAPITAL_OS_100_PERCENT_PDF_COMPLIANT.xlsx | B21: GOVERNANCE_LOG | C21: D1 | D21: Risk Mode
A22: DYZEN_CAPITAL_OS_100_PERCENT_PDF_COMPLIANT.xlsx | B22: GOVERNANCE_LOG | C22: H1 | D22: Open Risk Status
A23: DYZEN_CAPITAL_OS_100_PERCENT_PDF_COMPLIANT.xlsx | B23: GOVERNANCE_LOG | C23: C2 | D23: =REGIME_ENGINE!B7
A24: DYZEN_CAPITAL_OS_100_PERCENT_PDF_COMPLIANT.xlsx | B24: GOVERNANCE_LOG | C24: D2 | D24: =DRAWDOWN_ENGINE!B6
A25: DYZEN_CAPITAL_OS_100_PERCENT_PDF_COMPLIANT.xlsx | B25: GOVERNANCE_LOG | C25: H2 | D25: =OPEN_RISK_ENGINE!B9
A26: DYZEN_CAPITAL_OS_100_PERCENT_PDF_COMPLIANT.xlsx | B26: OPEN_RISK_ENGINE | C26: A1 | D26: OPEN RISK ENGINE — Portfolio Level Control
A27: DYZEN_CAPITAL_OS_100_PERCENT_PDF_COMPLIANT.xlsx | B27: OPEN_RISK_ENGINE | C27: A3 | D27: Per Trade Risk %
A28: DYZEN_CAPITAL_OS_100_PERCENT_PDF_COMPLIANT.xlsx | B28: OPEN_RISK_ENGINE | C28: A5 | D28: Current Open Risk %
A29: DYZEN_CAPITAL_OS_100_PERCENT_PDF_COMPLIANT.xlsx | B29: OPEN_RISK_ENGINE | C29: A7 | D29: Max Allowed Open Risk %
A30: DYZEN_CAPITAL_OS_100_PERCENT_PDF_COMPLIANT.xlsx | B30: OPEN_RISK_ENGINE | C30: A9 | D30: Open Risk Status
A31: DYZEN_CAPITAL_OS_100_PERCENT_PDF_COMPLIANT.xlsx | B31: OPEN_RISK_ENGINE | C31: B9 | D31: =IF(B5>=B7,"RISK_LIMIT_REACHED","SAFE")
A32: DYZEN_CAPITAL_OS_100_PERCENT_PDF_COMPLIANT.xlsx | B32: MAX_LOSS_ENGINE | C32: A4 | D32: Current Drawdown %
A33: DYZEN_CAPITAL_OS_3.0_RISK_CENTRIC.xlsx | B33: INPUTS | C33: A1 | D33: Capital
A34: DYZEN_CAPITAL_OS_3.0_RISK_CENTRIC.xlsx | B34: INPUTS | C34: B1 | D34: Risk Appetite
A35: DYZEN_CAPITAL_OS_3.0_RISK_CENTRIC.xlsx | B35: RISK_ENGINE | C35: B1 | D35: Base_Risk
A36: DYZEN_CAPITAL_OS_3.0_RISK_CENTRIC.xlsx | B36: REGIME_ENGINE | C36: G1 | D36: REGIME_OUTPUT
A37: DYZEN_CAPITAL_OS_3.0_RISK_CENTRIC.xlsx | B37: VOL_ADAPTATION | C37: D2 | D37: =RISK_CORE!F2
A38: DYZEN_CAPITAL_OS_3.0_RISK_CENTRIC.xlsx | B38: STRUCTURE_ENGINE | C38: B2 | D38: =IF(AND(A2="BULLISH",REGIME_ENGINE!G2<>"CHOP",RISK_CORE!G2=TRUE),"BUY","WAIT")
A39: DYZEN_CAPITAL_OS_3.0_RISK_CENTRIC.xlsx | B39: BEAR_STRUCTURE | C39: B2 | D39: =IF(AND(A2=TRUE,REGIME_ENGINE!G2<>"CHOP"),"SHORT","WAIT")
A40: DYZEN_CAPITAL_OS_3.0_RISK_CENTRIC.xlsx | B40: SELL_PROFILE_FIXED | C40: A1 | D40: SELL_CONF
...

Sheet SELL_LOGIC_EVOLUTION
A1: Version | B1: Core Logic | C1: Key Filter | D1: Risk Behavior | E1: Improvement
A2: V2_PARTIAL_RUNNER | B2: Profit Gate + 30% Partial | C2: Min R threshold | D2: Keeps runner exposure | E2: Introduced partial scaling logic
A3: V3_PROFIT_GATED | B3: Strict Min R before SELL | C3: Profit Gate enforced | D3: Reduces early exits | E3: Stronger profit validation
A4: DEEP_PASS | B4: Multi-layer consensus | C4: Structure+Volume+Risk aligned | D4: Institutional filtering | E4: Full confirmation gating
A5: PATCHED | B5: Confidence ≥0.64 + Structure Required | C5: SELL_CONFIDENCE_MIN raised | D5: Noise suppression | E5: Fix permissive SELL issue
A6: AB_READY | B6: Conservative vs Aggressive profiles | C6: Live performance comparison | D6: Adaptive tuning | E6: Profile optimization engine

Sheet WEIGHT_THRESHOLD_MATRIX
A1: Component | B1: Normalized Weight | C1: Threshold | D1: Purpose
A2: Trend Strength | B2: 0.25 | C2: ≥0.60 | D2: Macro bias filter
A3: Structure Validation | B3: 0.2 | C3: TRUE required | D3: Market structure confirmation
A4: Volume Confirmation | B4: 0.15 | C4: ≥0.50 | D4: Liquidity validation
A5: Risk State Modifier | B5: 0.15 | C5: State != KILL | D5: Capital protection override
A6: Confidence Score | B6: 0.15 | C6: ≥0.64 | D6: Primary SELL gate
A7: Volatility Regime | B7: 0.1 | C7: Allowed band only | D7: Avoid extreme volatility regimes

Sheet CONFLICT_OVERRIDE
A1: Priority | B1: Rule | C1: Override Effect
A2: 1 | B2: KILL_STATE | C2: Stops all trading immediately
A3: 2 | B3: Exposure_Cap_Breach | C3: Blocks new entries
A4: 3 | B4: Structure_Invalid | C4: Blocks SELL execution
A5: 4 | B5: Confidence < 0.64 | C5: Blocks SELL
A6: 5 | B6: Profit_Gate_Not_Met | C6: Blocks SELL
A7: 6 | B7: Trend_Weak | C7: Reduces position size only

Sheet UNIFIED_MASTER_ENGINE
A1: Metric | B1: Input | C1: Weight | D1: Weighted Score
A2: Trend Strength | C2: 0.25 | D2: =B2*C2
A3: Structure Score | C3: 0.2 | D3: =B3*C3
A4: Volume Score | C4: 0.15 | D4: =B4*C4
A5: Risk Modifier | C5: 0.15 | D5: =B5*C5
A6: Confidence Score | C6: 0.15 | D6: =B6*C6
A7: Volatility Score | C7: 0.1 | D7: =B7*C7
A8: TOTAL_SCORE | D8: =SUM(D2:D7)

Sheet BACKTEST_SIMULATION
A1: Trade # | B1: Entry | C1: Exit | D1: R Multiple | E1: Position Size | F1: PnL | G1: Equity
A2: 1 | D2: =IF(B2="",0,(C2-B2)/B2) | F2: =D2*E2 | G2: =IF(A2=1,10000, G1+F2)

Sheet MONTE_CARLO_SIM
A1: Simulation # | B1: Win Rate | C1: Avg R | D1: Risk % | E1: Expected Return
A2: 1 | E2: =B2*C2*D2

Sheet VOLATILITY_REGIME
A1: ATR | B1: ATR Moving Avg | C1: Volatility Ratio | D1: Regime
C2: =IF(B2=0,0,A2/B2) | D2: =IF(C2>1.5,"HIGH",IF(C2<0.7,"LOW","NORMAL"))

Sheet EQUITY_ADAPTIVE_SCALING
A1: Current Equity | B1: Peak Equity | C1: Drawdown % | D1: Base Risk % | E1: Adjusted Risk %
C2: =IF(B2=0,0,(B2-A2)/B2) | E2: =IF(C2>0.10,B2*0.5,B2)

Sheet TRADE_CLUSTER_PROTECTION
A1: Open Trades | B1: Max Allowed | C1: Cluster Status
C2: =IF(A2>B2,"BLOCK_NEW_TRADES","ALLOW")

Sheet AUTO_WEIGHT_ADJUSTER
A1: Metric | B1: Current Value | C1: Target | D1: Adjustment Factor
A2: Win Rate | D2: =IF(B2<C2,0.9,1.05)

Sheet MONTE_CARLO_1000
A1: Iteration | B1: Random Win/Loss | C1: R Multiple | D1: Risk % | E1: Return
A2: 1 | B2: =IF(RAND()<0.55,1,-1) | C2: =IF(B2=1,2,-1) | D2: 0.01 | E2: =B2*C2*D2
A3: 2 | B3: =IF(RAND()<0.55,1,-1) | C3: =IF(B3=1,2,-1) | D3: 0.01 | E3: =B3*C3*D3
A4: 3 | B4: =IF(RAND()<0.55,1,-1) | C4: =IF(B4=1,2,-1) | D4: 0.01 | E4: =B4*C4*D4
A5: 4 | B5: =IF(RAND()<0.55,1,-1) | C5: =IF(B5=1,2,-1) | D5: 0.01 | E5: =B5*C5*D5
A6: 5 | B6: =IF(RAND()<0.55,1,-1) | C6: =IF(B6=1,2,-1) | D6: 0.01 | E6: =B6*C6*D6
A7: 6 | B7: =IF(RAND()<0.55,1,-1) | C7: =IF(B7=1,2,-1) | D7: 0.01 | E7: =B7*C7*D7
A8: 7 | B8: =IF(RAND()<0.55,1,-1) | C8: =IF(B8=1,2,-1) | D8: 0.01 | E8: =B8*C8*D8
A9: 8 | B9: =IF(RAND()<0.55,1,-1) | C9: =IF(B9=1,2,-1) | D9: 0.01 | E9: =B9*C9*D9
A10: 9 | B10: =IF(RAND()<0.55,1,-1) | C10: =IF(B10=1,2,-1) | D10: 0.01 | E10: =B10*C10*D10
A11: 10 | B11: =IF(RAND()<0.55,1,-1) | C11: =IF(B11=1,2,-1) | D11: 0.01 | E11: =B11*C11*D11
A12: 11 | B12: =IF(RAND()<0.55,1,-1) | C12: =IF(B12=1,2,-1) | D12: 0.01 | E12: =B12*C12*D12
A13: 12 | B13: =IF(RAND()<0.55,1,-1) | C13: =IF(B13=1,2,-1) | D13: 0.01 | E13: =B13*C13*D13
... A1001: 1000 | B1001: =IF(RAND()<0.55,1,-1) | C1001: =IF(B1001=1,2,-1) | D1001: 0.01 | E1001: =B1001*C1001*D1001

Sheet DYNAMIC_WEIGHT_SWITCH
A1: Regime | B1: Trend Weight | C1: Structure Weight | D1: Volatility Weight
A2: HIGH | B2: 0.2 | C2: 0.25 | D2: 0.15
A3: NORMAL | B3: 0.25 | C3: 0.2 | D3: 0.1
A4: LOW | B4: 0.3 | C4: 0.15 | D4: 0.05

Sheet EQUITY_SLOPE_DETECTOR
A1: Recent Equity | B1: Previous Equity | C1: Slope | D1: Trend Status
C2: =A2-B2 | D2: =IF(C2>0,"UPTREND",IF(C2<0,"DOWNTREND","FLAT"))

Sheet CORRELATION_FILTER
A1: Asset 1 Return | B1: Asset 2 Return | C1: Correlation | D1: Trade Allowed
C2: =CORREL(A2:A21,B2:B21) | D2: =IF(C2>0.8,"BLOCK","ALLOW")

Sheet PORTFOLIO_ALLOCATOR
A1: Asset | B1: Signal Score | C1: Allocated % | D1: Capital Allocation
A2: BTC | C2: =B2/SUM(B2:B6) | D2: =C2*100000
A3: ETH | C3: =B3/SUM(B2:B6) | D3: =C3*100000
A4: SOL | C4: =B4/SUM(B2:B6) | D4: =C4*100000
A5: BNB | C5: =B5/SUM(B2:B6) | D5: =C5*100000
A6: XRP | C6: =B6/SUM(B2:B6) | D6: =C6*100000

Sheet PATH_MONTE_CARLO
A1: Step | B1: Random Outcome | C1: Return % | D1: Cumulative Equity
A2: 1 | B2: =IF(RAND()<0.55,1,-1) | C2: =B2*0.02 | D2: =100000*(1+C2)
A3: 2 | B3: =IF(RAND()<0.55,1,-1) | C3: =B3*0.02 | D3: =D2*(1+C3)
A4: 3 | B4: =IF(RAND()<0.55,1,-1) | C4: =B4*0.02 | D4: =D3*(1+C4)
A5: 4 | B5: =IF(RAND()<0.55,1,-1) | C5: =B5*0.02 | D5: =D4*(1+C5)
A6: 5 | B6: =IF(RAND()<0.55,1,-1) | C6: =B6*0.02 | D6: =D5*(1+C6)
A7: 6 | B7: =IF(RAND()<0.55,1,-1) | C7: =B7*0.02 | D7: =D6*(1+C7)
A8: 7 | B8: =IF(RAND()<0.55,1,-1) | C8: =B8*0.02 | D8: =D7*(1+C8)
A9: 8 | B9: =IF(RAND()<0.55,1,-1) | C9: =B9*0.02 | D9: =D8*(1+C9)
A10: 9 | B10: =IF(RAND()<0.55,1,-1) | C10: =B10*0.02 | D10: =D9*(1+C10)
A11: 10 | B11: =IF(RAND()<0.55,1,-1) | C11: =B11*0.02 | D11: =D10*(1+C11)
A12: 11 | B12: =IF(RAND()<0.55,1,-1) | C12: =B12*0.02 | D12: =D11*(1+C12)
A13: 12 | B13: =IF(RAND()<0.55,1,-1) | C13: =B13*0.02 | D13: =D12*(1+C13)
A14: 13 | B14: =IF(RAND()<0.55,1,-1) | C14: =B14*0.02 | D14: =D13*(1+C14)
... A201: 200 | B201: =IF(RAND()<0.55,1,-1) | C201: =B201*0.02 | D201: =D200*(1+C201)

Sheet KELLY_ADAPTIVE
A1: Win Rate (p) | B1: Reward/Risk (b) | C1: Kelly Fraction | D1: Adjusted Risk %
C2: =IF(B2=0,0,(A2*(B2+1)-1)/B2) | D2: =MAX(0,MIN(C2,0.05))

Sheet REGIME_PROB_MATRIX
A1: Regime | B1: Observed Frequency | C1: Probability | D1: Weight Multiplier
A2: HIGH | C2: =B2/SUM(B2:B4) | D2: =1+C2
A3: NORMAL | C3: =B3/SUM(B2:B4) | D3: =1+C3
A4: LOW | C4: =B4/SUM(B2:B4) | D4: =1+C4

Sheet BAYESIAN_WEIGHT_UPDATE
A1: Factor | B1: Prior Weight | C1: Likelihood | D1: Posterior Weight
A2: Trend | D2: =B2*C2/SUMPRODUCT(B2:B6,C2:C6)
A3: Structure | D3: =B3*C3/SUMPRODUCT(B2:B6,C2:C6)
A4: Volume | D4: =B4*C4/SUMPRODUCT(B2:B6,C2:C6)
A5: Volatility | D5: =B5*C5/SUMPRODUCT(B2:B6,C2:C6)
A6: Risk | D6: =B6*C6/SUMPRODUCT(B2:B6,C2:C6)

Sheet HMM_REGIME_MODEL
A1: Prev Regime | B1: Transition Prob | C1: Observed Signal | D1: Next Regime Prob
A2: HIGH | D2: =B2*C2

Sheet DRAWDOWN_PHASE_DETECTOR
A1: Current Equity | B1: Peak Equity | C1: Drawdown % | D1: Phase
C2: =IF(B2=0,0,(B2-A2)/B2) | D2: =IF(C2>0.20,"CRISIS",IF(C2>0.10,"WARNING","STABLE"))

Sheet VOL_OF_VOL_FILTER
A1: ATR Series | B1: ATR StdDev | C1: Vol-of-Vol Ratio | D1: Filter Status
B2: =STDEV(A2:A21) | C2: =IF(A2=0,0,B2/A2) | D2: =IF(C2>0.5,"UNSTABLE","STABLE")

Sheet CAPITAL_VELOCITY_OPTIMIZER
A1: Net Profit | B1: Time Period | C1: Capital Velocity | D1: Optimization Signal
C2: =IF(B2=0,0,A2/B2) | D2: =IF(C2>0.02,"ACCELERATE","HOLD")

Sheet SELF_LEARNING_ENGINE
A1: Metric | B1: Current | C1: Target | D1: Adjustment Multiplier
A2: Win Rate | D2: =IF(B2<C2,0.95,1.05)
A3: Profit Factor | D3: =IF(B3<C3,0.97,1.03)
A4: Max Drawdown | D4: =IF(B4>C4,0.90,1.02)

Sheet AUTONOMOUS_REALLOCATOR
A1: Strategy | B1: Performance Score | C1: Capital % | D1: Allocated Capital
A2: Strategy_A | C2: =B2/SUM(B2:B6) | D2: =C2*100000
A3: Strategy_B | C3: =B3/SUM(B2:B6) | D3: =C3*100000
A4: Strategy_C | C4: =B4/SUM(B2:B6) | D4: =C4*100000
A5: Strategy_D | C5: =B5/SUM(B2:B6) | D5: =C5*100000
A6: Strategy_E | C6: =B6/SUM(B2:B6) | D6: =C6*100000

Sheet ADAPTIVE_RISK_LOOP
A1: Equity Slope | B1: Volatility Regime | C1: Risk Base % | D1: Final Risk %
D2: =IF(A2="UPTREND",C2*1.1,IF(A2="DOWNTREND",C2*0.7,C2))

Sheet SYSTEM_EVOLUTION_TRACKER
A1: Cycle # | B1: Weight Set ID | C1: Risk Level | D1: Capital Growth % | E1: Keep/Replace
A2: 1 | E2: =IF(D2>0,"KEEP","REPLACE")

Sheet FUND_SIM_GRID
A1: Strategy ID | B1: Weight Set | C1: Risk % | D1: Regime Mode | E1: Equity | F1: Sharpe Proxy | G1: Drawdown % | H1: Composite Score
A2: STRAT_1 | H2: =E2*0.4 + F2*0.3 - G2*0.3
A3: STRAT_2 | H3: =E3*0.4 + F3*0.3 - G3*0.3
A4: STRAT_3 | H4: =E4*0.4 + F4*0.3 - G4*0.3
A5: STRAT_4 | H5: =E5*0.4 + F5*0.3 - G5*0.3
A6: STRAT_5 | H6: =E6*0.4 + F6*0.3 - G6*0.3

Sheet PARALLEL_BACKTEST_MATRIX
A1: Strategy | B1: Trade # | C1: R Multiple | D1: Risk % | E1: PnL | F1: Cumulative Equity
A2: STRAT_1 | B2: 1 | E2: =C2*D2 | F2: =100000+E2

Sheet SURVIVAL_SELECTION
A1: Strategy ID | B1: Composite Score | C1: Rank | D1: Status
A2: STRAT_1 | C2: =RANK(B2,B2:B6) | D2: =IF(C2<=2,"SURVIVE","REPLACE")

Sheet CAPITAL_REDISTRIBUTION
A1: Strategy | B1: Score | C1: Allocation % | D1: Capital Assigned
A2: STRAT_1 | C2: =B2/SUM(B2:B6) | D2: =C2*100000

Sheet FUND_META_DASHBOARD
A1: Metric | B1: Value
A2: Total Fund Equity
A3: Best Strategy ID
A4: Worst Strategy ID
A5: Fund-Level Sharpe Proxy
A6: Fund Max Drawdown

Sheet STRATEGY_MUTATION_ENGINE
A1: Parent Strategy | B1: Base Weight | C1: Mutation Factor | D1: Mutated Weight
A2: STRAT_1 | C2: =RAND()*0.2-0.1 | D2: =B2*(1+C2)

Sheet PARAMETER_BREEDING_LAB
A1: Parent A Score | B1: Parent B Score | C1: Offspring Weight | D1: Selection Bias
C2: =AVERAGE(A2,B2) | D2: =IF(A2>B2,"A_DOMINANT","B_DOMINANT")

Sheet DNA_SWAP_MATRIX
A1: Strategy A | B1: Strategy B | C1: Swap % | D1: Resulting Hybrid Score
A2: STRAT_1 | B2: STRAT_2 | C2: 0.5 | D2: =RAND()*100

Sheet EVOLUTION_SCORE_MEMORY
A1: Generation # | B1: Strategy ID | C1: Score | D1: Retained?
A2: 1 | B2: STRAT_1 | D2: =IF(C2>50,"YES","NO")

Sheet EVOLUTION_CONTROL_PANEL
A1: Mutation Rate | B1: Selection Pressure | C1: Max Generations | D1: Evolution Active?
A2: 0.1 | B2: 0.5 | C2: 10 | D2: TRUE

Sheet SELF_IMPROVING_REGIME
A1: Regime | B1: Win Rate | C1: Avg R | D1: Performance Score | E1: Weight Multiplier
A2: TREND | D2: =B2*C2 | E2: =IF(D2>0,1.1,0.9)
A3: RANGE | D3: =B3*C3 | E3: =IF(D3>0,1.1,0.9)
A4: VOLATILE | D4: =B4*C4 | E4: =IF(D4>0,1.1,0.9)

Sheet CROSS_MARKET_ADAPTIVE
A1: Asset A Return | B1: Asset B Return | C1: Correlation | D1: Allocation Adjustment
C2: =CORREL(A2:A21,B2:B21) | D2: =IF(C2>0.7,0.8,1.0)

Sheet CAPITAL_FLOW_MODEL
A1: Sector | B1: Volume Change % | C1: Momentum Score | D1: Capital Bias
A2: CRYPTO | D2: =IF(B2>0.05,"OVERWEIGHT","NEUTRAL")
A3: EQUITIES | D3: =IF(B3>0.05,"OVERWEIGHT","NEUTRAL")
A4: FOREX | D4: =IF(B4>0.05,"OVERWEIGHT","NEUTRAL")

Sheet META_FUND_LAYER
A1: Fund ID | B1: Fund Score | C1: Allocation % | D1: Capital Assigned
A2: FUND_A | C2: =B2/SUM(B2:B5) | D2: =C2*500000
A3: FUND_B | C3: =B3/SUM(B2:B5) | D3: =C3*500000
A4: FUND_C | C4: =B4/SUM(B2:B5) | D4: =C4*500000
A5: FUND_D | C5: =B5/SUM(B2:B5) | D5: =C5*500000

Sheet GLOBAL_LIQUIDITY_PROXY
A1: Liquidity Indicator 1 | B1: Indicator 2 | C1: Composite Liquidity Score | D1: Liquidity Regime
C2: =AVERAGE(A2:B2) | D2: =IF(C2>0.6,"EXPANSION",IF(C2<0.4,"CONTRACTION","NEUTRAL"))

Sheet MACRO_RISK_THERMOMETER
A1: Volatility Index | B1: Credit Spread | C1: Macro Risk Score | D1: Risk Level
C2: =AVERAGE(A2:B2) | D2: =IF(C2>0.7,"HIGH_RISK",IF(C2>0.4,"MEDIUM_RISK","LOW_RISK"))

Sheet CAPITAL_SHOCK_ABSORBER
A1: Equity Change % | B1: Volatility Spike | C1: Shock Score | D1: Action
C2: =ABS(A2)*B2 | D2: =IF(C2>0.1,"REDUCE_EXPOSURE","NORMAL")

Sheet CAPITAL_PRESERVATION_MODE
A1: Drawdown % | B1: Macro Risk Level | C1: Liquidity Regime | D1: Capital Mode
D2: =IF(OR(A2>0.15,B2="HIGH_RISK",C2="CONTRACTION"),"DEFENSIVE_MODE","NORMAL_MODE")

Sheet GLOBAL_REGIME_SYNC
A1: Equity Regime | B1: Crypto Regime | C1: Macro Regime | D1: Synchronized State
D2: =IF(AND(A2=B2,B2=C2),A2,"DIVERGENCE")

Sheet CRISIS_SIM_MATRIX
A1: Shock Scenario | B1: Equity Impact % | C1: Volatility Multiplier | D1: Capital After Shock
A2: FLASH_CRASH | B2: -0.25 | C2: 2 | D2: =100000*(1+B2)
A3: LIQUIDITY_DRAIN | B3: -0.15 | C3: 1.5 | D3: =100000*(1+B3)
A4: MACRO_EVENT | B4: -0.2 | C4: 1.8 | D4: =100000*(1+B4)

Sheet STRESS_PROPAGATION_MODEL
A1: Source Market Shock | B1: Correlation Factor | C1: Propagated Impact % | D1: Adjusted Exposure
A2: CRYPTO | B2: -0.2 | C2: =A2*B2 | D2: =IF(C2<-0.1,"REDUCE","NORMAL")

Sheet RISK_OFF_ROTATION
A1: Macro Risk Level | B1: Liquidity Regime | C1: Risk-Off Signal | D1: Capital Allocation Shift
A2: HIGH_RISK | B2: CONTRACTION | C2: =IF(AND(A2="HIGH_RISK",B2="CONTRACTION"),"ACTIVATE","NO") | D2: =IF(C2="ACTIVATE",0.5,1.0)

Sheet GLOBAL_CAPITAL_CYCLE
A1: Liquidity Regime | B1: Macro Risk | C1: Capital Flow Bias | D1: Cycle Phase
D2: =IF(AND(A2="EXPANSION",B2="LOW_RISK"),"RISK_ON",IF(AND(A2="CONTRACTION",B2="HIGH_RISK"),"RISK_OFF","TRANSITION"))

Sheet SYSTEMIC_FRAGILITY_INDEX
A1: Volatility Spike | B1: Correlation Spike | C1: Drawdown Pressure | D1: Fragility Score | E1: Fragility Level
D2: =AVERAGE(A2:C2) | E2: =IF(D2>0.7,"EXTREME",IF(D2>0.4,"ELEVATED","STABLE"))

Sheet LIQUIDITY_VACUUM
A1: Volume Drop % | B1: Spread Widening | C1: Vacuum Score | D1: Vacuum Alert
C2: =ABS(A2)*B2 | D2: =IF(C2>0.1,"VACUUM_RISK","NORMAL")

Sheet CAPITAL_MIGRATION_MATRIX
A1: Asset Class | B1: Performance Score | C1: Risk Score | D1: Migration Weight | E1: Capital Allocation
A2: CRYPTO | D2: =B2/(C2+0.0001) | E2: =D2/SUM(D2:D6)*1000000
A3: EQUITIES | D3: =B3/(C3+0.0001) | E3: =D3/SUM(D2:D6)*1000000
A4: FOREX | D4: =B4/(C4+0.0001) | E4: =D4/SUM(D2:D6)*1000000
A5: BONDS | D5: =B5/(C5+0.0001) | E5: =D5/SUM(D2:D6)*1000000
A6: CASH | D6: =B6/(C6+0.0001) | E6: =D6/SUM(D2:D6)*1000000

Sheet AI_DECISION_FUSION
A1: Signal Source | B1: Score | C1: Weight | D1: Weighted Output
A2: Technical Engine | D2: =B2*C2
A3: Regime Intelligence | D3: =B3*C3
A4: Macro Layer | D4: =B4*C4
A5: Capital Flow | D5: =B5*C5
A6: Risk Engine | D6: =B6*C6
A7: FINAL_AI_SCORE | D7: =SUM(D2:D6)

Sheet AI_CONFIDENCE_CALIBRATOR
A1: Predicted Edge | B1: Actual Outcome | C1: Calibration Error | D1: Confidence Adjustment
C2: =ABS(A2-B2) | D2: =IF(C2>0.1,0.9,1.05)

Sheet AI_RISK_DISTRIBUTOR
A1: AI Score | B1: Fragility Level | C1: Base Risk % | D1: Final Risk Allocation
D2: =IF(B2="EXTREME",C2*0.5,IF(B2="ELEVATED",C2*0.8,C2*(A2+0.5)))

Sheet AI_AUTONOMOUS_LOOP
A1: Cycle # | B1: AI Score | C1: Risk Allocation | D1: Capital Growth % | E1: Reinforce?
A2: 1 | E2: =IF(D2>0,"REINFORCE","RECALIBRATE")

Sheet AI_META_DASHBOARD
A1: Metric | B1: Value
A2: Global AI Score
A3: System Risk State
A4: Capital Mode
A5: Current Fragility
A6: Global Cycle Phase

Sheet LIVE_MACRO_RISK_GATE
A1: Liquidity Regime | B1: Macro Risk Level | C1: Shock Absorber | D1: Trade Permission
D2: =IF(OR(A2="CONTRACTION",B2="HIGH_RISK",C2="REDUCE_EXPOSURE"),"BLOCK","ALLOW")

Sheet LIVE_STRATEGY_SELECTOR
A1: Strategy ID | B1: Composite Score | C1: Rank | D1: Active?
A2: STRAT_1 | B2: =IFERROR(AI_DECISION_FUSION!A2*ALPHA_PERSISTENCE_ENGINE!D2,AI_DECISION_FUSION!A2) | C2: =RANK(B2,B2:B6) | D2: =IF(C2<=2,"YES","NO")
A3: STRAT_2 | B3: =IFERROR(AI_DECISION_FUSION!A2*ALPHA_PERSISTENCE_ENGINE!D2,AI_DECISION_FUSION!A2) | C3: =RANK(B3,B2:B6) | D3: =IF(C3<=2,"YES","NO")
A4: STRAT_3 | B4: =IFERROR(AI_DECISION_FUSION!A2*ALPHA_PERSISTENCE_ENGINE!D2,AI_DECISION_FUSION!A2) | C4: =RANK(B4,B2:B6) | D4: =IF(C4<=2,"YES","NO")
A5: STRAT_4 | B5: =IFERROR(AI_DECISION_FUSION!A2*ALPHA_PERSISTENCE_ENGINE!D2,AI_DECISION_FUSION!A2) | C5: =RANK(B5,B2:B6) | D5: =IF(C5<=2,"YES","NO")
A6: STRAT_5 | B6: =IFERROR(AI_DECISION_FUSION!A2*ALPHA_PERSISTENCE_ENGINE!D2,AI_DECISION_FUSION!A2) | C6: =RANK(B6,B2:B6) | D6: =IF(C6<=2,"YES","NO")

Sheet AI_MASTER_LIVE_DECISION
A1: AI Score | B1: Macro Gate | C1: Active Strategy | D1: Final Trade Decision | E1: Exit Guidance | F1: Final Trade Decision (LEGACY)
A2: 0 | B2: ALLOW | C2: YES | D2: HOLD | E2: HOLD | F2: =IF(AND(B2="ALLOW",C2="YES",A2>0.6,EXECUTION_EFFICIENCY_SCORE!C2>0.5,ALPHA_PERSISTENCE_ENGINE!D2>0.5),"EXECUTE","STAND_BY")

Sheet EXECUTION_EFFICIENCY_SCORE
A1: Spread Proxy | B1: Liquidity Score | C1: Execution Efficiency | D1: Execution Regime
A2: =IFERROR(1-GLOBAL_LIQUIDITY_PROXY!C2,0.5) | B2: =IFERROR(GLOBAL_LIQUIDITY_PROXY!C2,0.5) | C2: =MAX(0,MIN(1,0.5*B2+0.5*(1-A2))) | D2: =IF(C2>0.65,"HIGH_QUALITY",IF(C2<0.4,"POOR","NORMAL"))

Sheet ALPHA_PERSISTENCE_ENGINE
A1: Predicted Edge | B1: Calibration Adj | C1: Regime Stability | D1: Alpha Persistence Score | E1: Persistence Regime
A2: =IFERROR(AI_CONFIDENCE_CALIBRATOR!A2,0.5) | B2: =IFERROR(AI_CONFIDENCE_CALIBRATOR!D2,1) | C2: =IFERROR(IF(HMM_REGIME_MODEL!A2<>"",0.7,0.5),0.5) | D2: =MAX(0,MIN(1,A2*B2*C2)) | E2: =IF(D2>0.6,"PERSISTENT",IF(D2<0.35,"WEAK","UNSTABLE"))

Sheet ADAPTIVE_EXIT_MANAGER
A1: AI Decision | B1: Execution Quality | C1: Alpha Persistence | D1: Exit Pressure | E1: Exit Action
A2: =AI_MASTER_LIVE_DECISION!F2 | B2: =EXECUTION_EFFICIENCY_SCORE!C2 | C2: =ALPHA_PERSISTENCE_ENGINE!D2 | D2: =MAX(0,MIN(1,(1-B2)*0.5+(1-C2)*0.5)) | E2: =IF(D2>0.6,"AGGRESSIVE_EXIT",IF(D2>0.4,"PARTIAL_EXIT","HOLD"))
